<?xml version="1.0"?>
<robot name="my_robot" xmlns:xacro="http://www.ros.org/wiki/xacro">

    <!-- Xacro Properties -->
    <xacro:property name="base_length" value="0.6" />
    <xacro:property name="base_width" value="0.4" />
    <xacro:property name="base_height" value="0.2" />
    <xacro:property name="wheel_radius" value="0.1" />
    <xacro:property name="wheel_length" value="0.05" />

    <!-- Materials -->
    <material name="green">
        <color rgba="0 0.6 0 1"/>
    </material>

    <material name="white">
        <color rgba="1 1 1 1"/>
    </material>

    <material name="gray">
        <color rgba="0.7 0.7 0.7 1"/>
    </material>

    <!-- Virtual ground frame -->
    <link name="base_footprint"/>

    <!-- Base -->
    <link name="base_link">
        <visual>
            <geometry>
                <box size="${base_length} ${base_width} ${base_height}"/>
            </geometry>
            <origin xyz="0 0 ${base_height / 2.0}" rpy="0 0 0"/>
            <material name="green"/>
        </visual>
    </link>

    <joint name="base_joint" type="fixed">
        <parent link="base_footprint"/>
        <child link="base_link"/>
        <origin xyz="0 0 ${wheel_radius}" rpy="0 0 0"/>
    </joint>

    <!-- Lidar -->
    <link name="lidar">
        <visual>
            <geometry>
                <cylinder radius="${wheel_radius}" length="${wheel_length}"/>
            </geometry>
            <origin xyz="0 0 ${wheel_length / 2.0}" rpy="0 0 0"/>
            <material name="white"/>
        </visual>
    </link>

    <joint name="base_lidar_joint" type="fixed">
        <parent link="base_link"/>
        <child link="lidar"/>
        <origin xyz="${base_length / 4.0} 0 ${base_height}" rpy="0 0 0"/>
    </joint>

    <!-- LEFT WHEEL -->
    <link name="left_wheel">
        <visual>
            <geometry>
                <cylinder radius="${wheel_radius}" length="${wheel_length}"/>
            </geometry>
            <origin xyz="0 0 0" rpy="0 0 0"/>
            <material name="gray"/>
        </visual>
    </link>

    <joint name="base_left_wheel_joint" type="continuous">
        <parent link="base_link"/>
        <child link="left_wheel"/>
        <origin xyz="${base_length / 4.0} ${base_width / 2.0 + wheel_length / 2.0} ${wheel_radius}" rpy="${-pi / 2.0} 0 0"/>
        <axis xyz="0 0 1"/>
    </joint>

    <!-- RIGHT WHEEL -->
    <link name="right_wheel">
        <visual>
            <geometry>
                <cylinder radius="${wheel_radius}" length="${wheel_length}"/>
            </geometry>
            <origin xyz="0 0 0" rpy="0 0 0"/>
            <material name="gray"/>
        </visual>
    </link>

    <joint name="base_right_wheel_joint" type="continuous">
        <parent link="base_link"/>
        <child link="right_wheel"/>
        <origin xyz="${base_length / 4.0} ${-base_width / 2.0 - wheel_length / 2.0} ${wheel_radius}" rpy="${-pi / 2.0} 0 0"/>
        <axis xyz="0 0 1"/>
    </joint>

    <!-- CASTER -->
    <link name="caster_wheel">
        <visual>
            <geometry>
                <sphere radius="${wheel_radius / 2.0}"/>
            </geometry>
            <origin xyz="0 0 0" rpy="0 0 0"/>
            <material name="gray"/>
        </visual>
    </link>

    <joint name="base_caster_wheel_joint" type="fixed">
        <parent link="base_link"/>
        <child link="caster_wheel"/>
        <origin xyz="${-base_length / 2.0} 0 ${wheel_radius / 2.0}" rpy="0 0 0"/>
    </joint>

</robot>
